2023-12-19 13:42:09,445 ERROR: Exception on / [GET] [in /home/dargor/.local/share/virtualenvs/microblog-UE3ND_hc/lib/python3.10/site-packages/flask/app.py:825]
Traceback (most recent call last):
  File "/home/dargor/.local/share/virtualenvs/microblog-UE3ND_hc/lib/python3.10/site-packages/flask/app.py", line 1455, in wsgi_app
    response = self.full_dispatch_request()
  File "/home/dargor/.local/share/virtualenvs/microblog-UE3ND_hc/lib/python3.10/site-packages/flask/app.py", line 869, in full_dispatch_request
    rv = self.handle_user_exception(e)
  File "/home/dargor/.local/share/virtualenvs/microblog-UE3ND_hc/lib/python3.10/site-packages/flask/app.py", line 867, in full_dispatch_request
    rv = self.dispatch_request()
  File "/home/dargor/.local/share/virtualenvs/microblog-UE3ND_hc/lib/python3.10/site-packages/flask/app.py", line 852, in dispatch_request
    return self.ensure_sync(self.view_functions[rule.endpoint])(**view_args)
  File "/home/dargor/.local/share/virtualenvs/microblog-UE3ND_hc/lib/python3.10/site-packages/flask_login/utils.py", line 285, in decorated_view
    return current_app.login_manager.unauthorized()
  File "/home/dargor/.local/share/virtualenvs/microblog-UE3ND_hc/lib/python3.10/site-packages/flask_login/login_manager.py", line 196, in unauthorized
    redirect_url = make_login_url(login_view, next_url=request.url)
  File "/home/dargor/.local/share/virtualenvs/microblog-UE3ND_hc/lib/python3.10/site-packages/flask_login/utils.py", line 120, in login_url
    base = expand_login_view(login_view)
  File "/home/dargor/.local/share/virtualenvs/microblog-UE3ND_hc/lib/python3.10/site-packages/flask_login/utils.py", line 97, in expand_login_view
    return url_for(login_view)
  File "/home/dargor/.local/share/virtualenvs/microblog-UE3ND_hc/lib/python3.10/site-packages/flask/helpers.py", line 222, in url_for
    return current_app.url_for(
  File "/home/dargor/.local/share/virtualenvs/microblog-UE3ND_hc/lib/python3.10/site-packages/flask/app.py", line 1071, in url_for
    return self.handle_url_build_error(error, endpoint, values)
  File "/home/dargor/.local/share/virtualenvs/microblog-UE3ND_hc/lib/python3.10/site-packages/flask/app.py", line 1060, in url_for
    rv = url_adapter.build(  # type: ignore[union-attr]
  File "/home/dargor/.local/share/virtualenvs/microblog-UE3ND_hc/lib/python3.10/site-packages/werkzeug/routing/map.py", line 919, in build
    raise BuildError(endpoint, values, method, self)
werkzeug.routing.exceptions.BuildError: Could not build url for endpoint 'login'. Did you mean 'auth.login' instead?
2023-12-19 13:42:10,419 ERROR: Exception on / [GET] [in /home/dargor/.local/share/virtualenvs/microblog-UE3ND_hc/lib/python3.10/site-packages/flask/app.py:825]
Traceback (most recent call last):
  File "/home/dargor/.local/share/virtualenvs/microblog-UE3ND_hc/lib/python3.10/site-packages/flask/app.py", line 1455, in wsgi_app
    response = self.full_dispatch_request()
  File "/home/dargor/.local/share/virtualenvs/microblog-UE3ND_hc/lib/python3.10/site-packages/flask/app.py", line 869, in full_dispatch_request
    rv = self.handle_user_exception(e)
  File "/home/dargor/.local/share/virtualenvs/microblog-UE3ND_hc/lib/python3.10/site-packages/flask/app.py", line 867, in full_dispatch_request
    rv = self.dispatch_request()
  File "/home/dargor/.local/share/virtualenvs/microblog-UE3ND_hc/lib/python3.10/site-packages/flask/app.py", line 852, in dispatch_request
    return self.ensure_sync(self.view_functions[rule.endpoint])(**view_args)
  File "/home/dargor/.local/share/virtualenvs/microblog-UE3ND_hc/lib/python3.10/site-packages/flask_login/utils.py", line 285, in decorated_view
    return current_app.login_manager.unauthorized()
  File "/home/dargor/.local/share/virtualenvs/microblog-UE3ND_hc/lib/python3.10/site-packages/flask_login/login_manager.py", line 196, in unauthorized
    redirect_url = make_login_url(login_view, next_url=request.url)
  File "/home/dargor/.local/share/virtualenvs/microblog-UE3ND_hc/lib/python3.10/site-packages/flask_login/utils.py", line 120, in login_url
    base = expand_login_view(login_view)
  File "/home/dargor/.local/share/virtualenvs/microblog-UE3ND_hc/lib/python3.10/site-packages/flask_login/utils.py", line 97, in expand_login_view
    return url_for(login_view)
  File "/home/dargor/.local/share/virtualenvs/microblog-UE3ND_hc/lib/python3.10/site-packages/flask/helpers.py", line 222, in url_for
    return current_app.url_for(
  File "/home/dargor/.local/share/virtualenvs/microblog-UE3ND_hc/lib/python3.10/site-packages/flask/app.py", line 1071, in url_for
    return self.handle_url_build_error(error, endpoint, values)
  File "/home/dargor/.local/share/virtualenvs/microblog-UE3ND_hc/lib/python3.10/site-packages/flask/app.py", line 1060, in url_for
    rv = url_adapter.build(  # type: ignore[union-attr]
  File "/home/dargor/.local/share/virtualenvs/microblog-UE3ND_hc/lib/python3.10/site-packages/werkzeug/routing/map.py", line 919, in build
    raise BuildError(endpoint, values, method, self)
werkzeug.routing.exceptions.BuildError: Could not build url for endpoint 'login'. Did you mean 'auth.login' instead?
2023-12-19 13:42:10,757 ERROR: Exception on /favicon.ico [GET] [in /home/dargor/.local/share/virtualenvs/microblog-UE3ND_hc/lib/python3.10/site-packages/flask/app.py:825]
Traceback (most recent call last):
  File "/home/dargor/.local/share/virtualenvs/microblog-UE3ND_hc/lib/python3.10/site-packages/flask/app.py", line 867, in full_dispatch_request
    rv = self.dispatch_request()
  File "/home/dargor/.local/share/virtualenvs/microblog-UE3ND_hc/lib/python3.10/site-packages/flask/app.py", line 841, in dispatch_request
    self.raise_routing_exception(req)
  File "/home/dargor/.local/share/virtualenvs/microblog-UE3ND_hc/lib/python3.10/site-packages/flask/app.py", line 450, in raise_routing_exception
    raise request.routing_exception  # type: ignore
  File "/home/dargor/.local/share/virtualenvs/microblog-UE3ND_hc/lib/python3.10/site-packages/flask/ctx.py", line 353, in match_request
    result = self.url_adapter.match(return_rule=True)  # type: ignore
  File "/home/dargor/.local/share/virtualenvs/microblog-UE3ND_hc/lib/python3.10/site-packages/werkzeug/routing/map.py", line 624, in match
    raise NotFound() from None
werkzeug.exceptions.NotFound: 404 Not Found: The requested URL was not found on the server. If you entered the URL manually please check your spelling and try again.

During handling of the above exception, another exception occurred:

Traceback (most recent call last):
  File "/home/dargor/.local/share/virtualenvs/microblog-UE3ND_hc/lib/python3.10/site-packages/flask/app.py", line 1455, in wsgi_app
    response = self.full_dispatch_request()
  File "/home/dargor/.local/share/virtualenvs/microblog-UE3ND_hc/lib/python3.10/site-packages/flask/app.py", line 869, in full_dispatch_request
    rv = self.handle_user_exception(e)
  File "/home/dargor/.local/share/virtualenvs/microblog-UE3ND_hc/lib/python3.10/site-packages/flask/app.py", line 752, in handle_user_exception
    return self.handle_http_exception(e)
  File "/home/dargor/.local/share/virtualenvs/microblog-UE3ND_hc/lib/python3.10/site-packages/flask/app.py", line 727, in handle_http_exception
    return self.ensure_sync(handler)(e)
  File "/home/dargor/projects/microblog/app/errors/handlers.py", line 7, in not_found_error
    return render_template("errors/404.html"), 400
  File "/home/dargor/.local/share/virtualenvs/microblog-UE3ND_hc/lib/python3.10/site-packages/flask/templating.py", line 152, in render_template
    return _render(app, template, context)
  File "/home/dargor/.local/share/virtualenvs/microblog-UE3ND_hc/lib/python3.10/site-packages/flask/templating.py", line 133, in _render
    rv = template.render(context)
  File "/home/dargor/.local/share/virtualenvs/microblog-UE3ND_hc/lib/python3.10/site-packages/jinja2/environment.py", line 1301, in render
    self.environment.handle_exception()
  File "/home/dargor/.local/share/virtualenvs/microblog-UE3ND_hc/lib/python3.10/site-packages/jinja2/environment.py", line 936, in handle_exception
    raise rewrite_traceback_stack(source=source)
  File "/home/dargor/projects/microblog/app/templates/errors/404.html", line 1, in top-level template code
    {% extends "base.html" %}
  File "/home/dargor/projects/microblog/app/templates/base.html", line 36, in top-level template code
    <a class="nav-link" aria-current="page" href="{{ url_for('login') }}">Login</a>
  File "/home/dargor/.local/share/virtualenvs/microblog-UE3ND_hc/lib/python3.10/site-packages/flask/app.py", line 1071, in url_for
    return self.handle_url_build_error(error, endpoint, values)
  File "/home/dargor/.local/share/virtualenvs/microblog-UE3ND_hc/lib/python3.10/site-packages/flask/app.py", line 1060, in url_for
    rv = url_adapter.build(  # type: ignore[union-attr]
  File "/home/dargor/.local/share/virtualenvs/microblog-UE3ND_hc/lib/python3.10/site-packages/werkzeug/routing/map.py", line 919, in build
    raise BuildError(endpoint, values, method, self)
werkzeug.routing.exceptions.BuildError: Could not build url for endpoint 'login'. Did you mean 'auth.login' instead?
2023-12-19 13:42:33,670 INFO: Microblog started [in /home/dargor/projects/microblog/app/__init__.py:64]
