2023-12-16 23:24:50,176 ERROR: Exception on /user/john [GET] [in /home/dargor/.local/share/virtualenvs/microblog-UE3ND_hc/lib/python3.10/site-packages/flask/app.py:825]
Traceback (most recent call last):
  File "/home/dargor/.local/share/virtualenvs/microblog-UE3ND_hc/lib/python3.10/site-packages/flask/app.py", line 1455, in wsgi_app
    response = self.full_dispatch_request()
  File "/home/dargor/.local/share/virtualenvs/microblog-UE3ND_hc/lib/python3.10/site-packages/flask/app.py", line 869, in full_dispatch_request
    rv = self.handle_user_exception(e)
  File "/home/dargor/.local/share/virtualenvs/microblog-UE3ND_hc/lib/python3.10/site-packages/flask/app.py", line 867, in full_dispatch_request
    rv = self.dispatch_request()
  File "/home/dargor/.local/share/virtualenvs/microblog-UE3ND_hc/lib/python3.10/site-packages/flask/app.py", line 852, in dispatch_request
    return self.ensure_sync(self.view_functions[rule.endpoint])(**view_args)
  File "/home/dargor/.local/share/virtualenvs/microblog-UE3ND_hc/lib/python3.10/site-packages/flask_login/utils.py", line 290, in decorated_view
    return current_app.ensure_sync(func)(*args, **kwargs)
  File "/home/dargor/projects/microblog/app/routes.py", line 80, in user
    return render_template("user.html", user=user, posts=posts, form=form)
  File "/home/dargor/.local/share/virtualenvs/microblog-UE3ND_hc/lib/python3.10/site-packages/flask/templating.py", line 151, in render_template
    template = app.jinja_env.get_or_select_template(template_name_or_list)
  File "/home/dargor/.local/share/virtualenvs/microblog-UE3ND_hc/lib/python3.10/site-packages/jinja2/environment.py", line 1081, in get_or_select_template
    return self.get_template(template_name_or_list, parent, globals)
  File "/home/dargor/.local/share/virtualenvs/microblog-UE3ND_hc/lib/python3.10/site-packages/jinja2/environment.py", line 1010, in get_template
    return self._load_template(name, globals)
  File "/home/dargor/.local/share/virtualenvs/microblog-UE3ND_hc/lib/python3.10/site-packages/jinja2/environment.py", line 969, in _load_template
    template = self.loader.load(self, name, self.make_globals(globals))
  File "/home/dargor/.local/share/virtualenvs/microblog-UE3ND_hc/lib/python3.10/site-packages/jinja2/loaders.py", line 138, in load
    code = environment.compile(source, name, filename)
  File "/home/dargor/.local/share/virtualenvs/microblog-UE3ND_hc/lib/python3.10/site-packages/jinja2/environment.py", line 768, in compile
    self.handle_exception(source=source_hint)
  File "/home/dargor/.local/share/virtualenvs/microblog-UE3ND_hc/lib/python3.10/site-packages/jinja2/environment.py", line 936, in handle_exception
    raise rewrite_traceback_stack(source=source)
  File "/home/dargor/projects/microblog/app/templates/user.html", line 22, in template
    <form action="{{ url_for('follow'), username=user.username }}", method="post">
jinja2.exceptions.TemplateSyntaxError: expected token 'end of print statement', got '='
2023-12-16 23:25:20,495 ERROR: Exception on /user/john [GET] [in /home/dargor/.local/share/virtualenvs/microblog-UE3ND_hc/lib/python3.10/site-packages/flask/app.py:825]
Traceback (most recent call last):
  File "/home/dargor/.local/share/virtualenvs/microblog-UE3ND_hc/lib/python3.10/site-packages/flask/app.py", line 1455, in wsgi_app
    response = self.full_dispatch_request()
  File "/home/dargor/.local/share/virtualenvs/microblog-UE3ND_hc/lib/python3.10/site-packages/flask/app.py", line 869, in full_dispatch_request
    rv = self.handle_user_exception(e)
  File "/home/dargor/.local/share/virtualenvs/microblog-UE3ND_hc/lib/python3.10/site-packages/flask/app.py", line 867, in full_dispatch_request
    rv = self.dispatch_request()
  File "/home/dargor/.local/share/virtualenvs/microblog-UE3ND_hc/lib/python3.10/site-packages/flask/app.py", line 852, in dispatch_request
    return self.ensure_sync(self.view_functions[rule.endpoint])(**view_args)
  File "/home/dargor/.local/share/virtualenvs/microblog-UE3ND_hc/lib/python3.10/site-packages/flask_login/utils.py", line 290, in decorated_view
    return current_app.ensure_sync(func)(*args, **kwargs)
  File "/home/dargor/projects/microblog/app/routes.py", line 80, in user
    return render_template("user.html", user=user, posts=posts, form=form)
  File "/home/dargor/.local/share/virtualenvs/microblog-UE3ND_hc/lib/python3.10/site-packages/flask/templating.py", line 151, in render_template
    template = app.jinja_env.get_or_select_template(template_name_or_list)
  File "/home/dargor/.local/share/virtualenvs/microblog-UE3ND_hc/lib/python3.10/site-packages/jinja2/environment.py", line 1081, in get_or_select_template
    return self.get_template(template_name_or_list, parent, globals)
  File "/home/dargor/.local/share/virtualenvs/microblog-UE3ND_hc/lib/python3.10/site-packages/jinja2/environment.py", line 1010, in get_template
    return self._load_template(name, globals)
  File "/home/dargor/.local/share/virtualenvs/microblog-UE3ND_hc/lib/python3.10/site-packages/jinja2/environment.py", line 969, in _load_template
    template = self.loader.load(self, name, self.make_globals(globals))
  File "/home/dargor/.local/share/virtualenvs/microblog-UE3ND_hc/lib/python3.10/site-packages/jinja2/loaders.py", line 138, in load
    code = environment.compile(source, name, filename)
  File "/home/dargor/.local/share/virtualenvs/microblog-UE3ND_hc/lib/python3.10/site-packages/jinja2/environment.py", line 768, in compile
    self.handle_exception(source=source_hint)
  File "/home/dargor/.local/share/virtualenvs/microblog-UE3ND_hc/lib/python3.10/site-packages/jinja2/environment.py", line 936, in handle_exception
    raise rewrite_traceback_stack(source=source)
  File "/home/dargor/projects/microblog/app/templates/user.html", line 22, in template
    <form action="{{ url_for('follow'), username=user.username }}", method="post">
jinja2.exceptions.TemplateSyntaxError: expected token 'end of print statement', got '='
2023-12-16 23:33:42,536 INFO: Microblog started [in /home/dargor/projects/microblog/app/__init__.py:47]
2023-12-17 00:59:17,486 INFO: Microblog started [in /home/dargor/projects/microblog/app/__init__.py:47]
2023-12-17 01:01:38,682 INFO: Microblog started [in /home/dargor/projects/microblog/app/__init__.py:47]
2023-12-17 01:06:26,795 INFO: Microblog started [in /home/dargor/projects/microblog/app/__init__.py:47]
2023-12-17 01:17:51,327 INFO: Microblog started [in /home/dargor/projects/microblog/app/__init__.py:47]
2023-12-17 01:18:14,394 INFO: Microblog started [in /home/dargor/projects/microblog/app/__init__.py:47]
2023-12-17 01:27:41,632 INFO: Microblog started [in /home/dargor/projects/microblog/app/__init__.py:47]
2023-12-17 01:37:54,990 INFO: Microblog started [in /home/dargor/projects/microblog/app/__init__.py:47]
2023-12-17 01:38:27,127 ERROR: Exception on /user/john [GET] [in /home/dargor/.local/share/virtualenvs/microblog-UE3ND_hc/lib/python3.10/site-packages/flask/app.py:825]
Traceback (most recent call last):
  File "/home/dargor/.local/share/virtualenvs/microblog-UE3ND_hc/lib/python3.10/site-packages/flask/app.py", line 1455, in wsgi_app
    response = self.full_dispatch_request()
  File "/home/dargor/.local/share/virtualenvs/microblog-UE3ND_hc/lib/python3.10/site-packages/flask/app.py", line 869, in full_dispatch_request
    rv = self.handle_user_exception(e)
  File "/home/dargor/.local/share/virtualenvs/microblog-UE3ND_hc/lib/python3.10/site-packages/flask/app.py", line 867, in full_dispatch_request
    rv = self.dispatch_request()
  File "/home/dargor/.local/share/virtualenvs/microblog-UE3ND_hc/lib/python3.10/site-packages/flask/app.py", line 852, in dispatch_request
    return self.ensure_sync(self.view_functions[rule.endpoint])(**view_args)
  File "/home/dargor/.local/share/virtualenvs/microblog-UE3ND_hc/lib/python3.10/site-packages/flask_login/utils.py", line 290, in decorated_view
    return current_app.ensure_sync(func)(*args, **kwargs)
  File "/home/dargor/projects/microblog/app/routes.py", line 83, in user
    user = db.first_or404(sa.select(User).where(User.username == username))
  File "/home/dargor/.local/share/virtualenvs/microblog-UE3ND_hc/lib/python3.10/site-packages/flask_sqlalchemy/extension.py", line 1008, in __getattr__
    raise AttributeError(name)
AttributeError: first_or404
2023-12-17 01:38:28,358 ERROR: Exception on /user/john [GET] [in /home/dargor/.local/share/virtualenvs/microblog-UE3ND_hc/lib/python3.10/site-packages/flask/app.py:825]
Traceback (most recent call last):
  File "/home/dargor/.local/share/virtualenvs/microblog-UE3ND_hc/lib/python3.10/site-packages/flask/app.py", line 1455, in wsgi_app
    response = self.full_dispatch_request()
  File "/home/dargor/.local/share/virtualenvs/microblog-UE3ND_hc/lib/python3.10/site-packages/flask/app.py", line 869, in full_dispatch_request
    rv = self.handle_user_exception(e)
  File "/home/dargor/.local/share/virtualenvs/microblog-UE3ND_hc/lib/python3.10/site-packages/flask/app.py", line 867, in full_dispatch_request
    rv = self.dispatch_request()
  File "/home/dargor/.local/share/virtualenvs/microblog-UE3ND_hc/lib/python3.10/site-packages/flask/app.py", line 852, in dispatch_request
    return self.ensure_sync(self.view_functions[rule.endpoint])(**view_args)
  File "/home/dargor/.local/share/virtualenvs/microblog-UE3ND_hc/lib/python3.10/site-packages/flask_login/utils.py", line 290, in decorated_view
    return current_app.ensure_sync(func)(*args, **kwargs)
  File "/home/dargor/projects/microblog/app/routes.py", line 83, in user
    user = db.first_or404(sa.select(User).where(User.username == username))
  File "/home/dargor/.local/share/virtualenvs/microblog-UE3ND_hc/lib/python3.10/site-packages/flask_sqlalchemy/extension.py", line 1008, in __getattr__
    raise AttributeError(name)
AttributeError: first_or404
2023-12-17 01:39:32,149 INFO: Microblog started [in /home/dargor/projects/microblog/app/__init__.py:47]
2023-12-18 10:31:52,062 INFO: Microblog started [in /home/dargor/projects/microblog/app/__init__.py:50]
2023-12-18 11:39:32,152 INFO: Microblog started [in /home/dargor/projects/microblog/app/__init__.py:50]
